<?xml version="1.0" ?>
<robot name="capstone_design" xmlns:xacro="http://www.ros.org/wiki/xacro">

<xacro:include filename="$(find capstone_design_description)/urdf/materials.xacro" />
<xacro:include filename="$(find capstone_design_description)/urdf/capstone_design.trans" />
<xacro:include filename="$(find capstone_design_description)/urdf/capstone_design.gazebo" />
<link name="base_link">
  <inertial>
    <origin xyz="0.0 -0.18760221512473715 0.11026773981655406" rpy="0 0 0"/>
    <mass value="244.42049863775813"/>
    <inertia ixx="8.801276" iyy="5.776252" izz="8.8371" ixy="0.0" iyz="1.716086" ixz="0.0"/>
  </inertial>
  <visual>
    <origin xyz="0 0 0" rpy="0 0 0"/>
    <geometry>
      <mesh filename="file://$(find capstone_design_description)/meshes/base_link.stl" scale="0.001 0.001 0.001"/>
    </geometry>
    <material name="silver"/>
  </visual>
  <collision>
    <origin xyz="0 0 0" rpy="0 0 0"/>
    <geometry>
      <mesh filename="file://$(find capstone_design_description)/meshes/base_link.stl" scale="0.001 0.001 0.001"/>
    </geometry>
  </collision>
</link>

<link name="arm_base_link_1">
  <inertial>
    <origin xyz="4.020849375084743e-17 0.0 0.0049999999999999906" rpy="0 0 0"/>
    <mass value="3.551256335617901"/>
    <inertia ixx="0.012814" iyy="0.012814" izz="0.025569" ixy="0.0" iyz="0.0" ixz="0.0"/>
  </inertial>
  <visual>
    <origin xyz="-0.0 -0.0 -0.0918" rpy="0 0 0"/>
    <geometry>
      <mesh filename="file://$(find capstone_design_description)/meshes/arm_base_link_1.stl" scale="0.001 0.001 0.001"/>
    </geometry>
    <material name="silver"/>
  </visual>
  <collision>
    <origin xyz="-0.0 -0.0 -0.0918" rpy="0 0 0"/>
    <geometry>
      <mesh filename="file://$(find capstone_design_description)/meshes/arm_base_link_1.stl" scale="0.001 0.001 0.001"/>
    </geometry>
  </collision>
</link>

<link name="link1_1">
  <inertial>
    <origin xyz="2.0030450291854913e-17 2.0030450291854907e-17 0.04290880959465923" rpy="0 0 0"/>
    <mass value="7.128679889758317"/>
    <inertia ixx="0.014169" iyy="0.028332" izz="0.02758" ixy="-0.0" iyz="0.0" ixz="0.0"/>
  </inertial>
  <visual>
    <origin xyz="-0.0 -0.0 -0.1018" rpy="0 0 0"/>
    <geometry>
      <mesh filename="file://$(find capstone_design_description)/meshes/link1_1.stl" scale="0.001 0.001 0.001"/>
    </geometry>
    <material name="silver"/>
  </visual>
  <collision>
    <origin xyz="-0.0 -0.0 -0.1018" rpy="0 0 0"/>
    <geometry>
      <mesh filename="file://$(find capstone_design_description)/meshes/link1_1.stl" scale="0.001 0.001 0.001"/>
    </geometry>
  </collision>
</link>

<link name="link2_1">
  <inertial>
    <origin xyz="0.03360000772838613 -8.485027970501936e-11 0.06805286707917996" rpy="0 0 0"/>
    <mass value="6.954595389355063"/>
    <inertia ixx="0.045406" iyy="0.045852" izz="0.00637" ixy="-0.0" iyz="0.0" ixz="-0.0"/>
  </inertial>
  <visual>
    <origin xyz="0.0336 -0.0 -0.1668" rpy="0 0 0"/>
    <geometry>
      <mesh filename="file://$(find capstone_design_description)/meshes/link2_1.stl" scale="0.001 0.001 0.001"/>
    </geometry>
    <material name="silver"/>
  </visual>
  <collision>
    <origin xyz="0.0336 -0.0 -0.1668" rpy="0 0 0"/>
    <geometry>
      <mesh filename="file://$(find capstone_design_description)/meshes/link2_1.stl" scale="0.001 0.001 0.001"/>
    </geometry>
  </collision>
</link>

<link name="link3_1">
  <inertial>
    <origin xyz="0.030000023541393757 4.114813245135107e-18 0.02802505675959771" rpy="0 0 0"/>
    <mass value="3.999606826289236"/>
    <inertia ixx="0.014123" iyy="0.013491" izz="0.002566" ixy="0.0" iyz="-0.0" ixz="-0.0"/>
  </inertial>
  <visual>
    <origin xyz="0.03 -0.0 -0.370357" rpy="0 0 0"/>
    <geometry>
      <mesh filename="file://$(find capstone_design_description)/meshes/link3_1.stl" scale="0.001 0.001 0.001"/>
    </geometry>
    <material name="silver"/>
  </visual>
  <collision>
    <origin xyz="0.03 -0.0 -0.370357" rpy="0 0 0"/>
    <geometry>
      <mesh filename="file://$(find capstone_design_description)/meshes/link3_1.stl" scale="0.001 0.001 0.001"/>
    </geometry>
  </collision>
</link>

<link name="hand_link_1">
  <inertial>
    <origin xyz="3.255267775751497e-05 0.0010470921107968664 0.021378963563369324" rpy="0 0 0"/>
    <mass value="0.34655707869237173"/>
    <inertia ixx="0.0002" iyy="0.000282" izz="0.000135" ixy="-3e-06" iyz="-1.2e-05" ixz="-5.4e-05"/>
  </inertial>
  <visual>
    <origin xyz="0.008 -0.0 -0.544257" rpy="0 0 0"/>
    <geometry>
      <mesh filename="file://$(find capstone_design_description)/meshes/hand_link_1.stl" scale="0.001 0.001 0.001"/>
    </geometry>
    <material name="silver"/>
  </visual>
  <collision>
    <origin xyz="0.008 -0.0 -0.544257" rpy="0 0 0"/>
    <geometry>
      <mesh filename="file://$(find capstone_design_description)/meshes/hand_link_1.stl" scale="0.001 0.001 0.001"/>
    </geometry>
  </collision>
</link>

<link name="left_gripper_link_1">
  <inertial>
    <origin xyz="-6.42194630806614e-14 -0.002499999999999998 0.014999999999971148" rpy="0 0 0"/>
    <mass value="0.01720971564055042"/>
    <inertia ixx="3e-06" iyy="3e-06" izz="0.0" ixy="-0.0" iyz="-0.0" ixz="0.0"/>
  </inertial>
  <visual>
    <origin xyz="0.03 -0.005 -0.591757" rpy="0 0 0"/>
    <geometry>
      <mesh filename="file://$(find capstone_design_description)/meshes/left_gripper_link_1.stl" scale="0.001 0.001 0.001"/>
    </geometry>
    <material name="silver"/>
  </visual>
  <collision>
    <origin xyz="0.03 -0.005 -0.591757" rpy="0 0 0"/>
    <geometry>
      <mesh filename="file://$(find capstone_design_description)/meshes/left_gripper_link_1.stl" scale="0.001 0.001 0.001"/>
    </geometry>
  </collision>
</link>

<link name="right_gripper_link_1">
  <inertial>
    <origin xyz="-6.42715047849407e-14 -0.002499999999999998 0.014999999999970925" rpy="0 0 0"/>
    <mass value="0.01720971564055051"/>
    <inertia ixx="3e-06" iyy="3e-06" izz="0.0" ixy="0.0" iyz="-0.0" ixz="0.0"/>
  </inertial>
  <visual>
    <origin xyz="-0.03 -0.005 -0.591757" rpy="0 0 0"/>
    <geometry>
      <mesh filename="file://$(find capstone_design_description)/meshes/right_gripper_link_1.stl" scale="0.001 0.001 0.001"/>
    </geometry>
    <material name="silver"/>
  </visual>
  <collision>
    <origin xyz="-0.03 -0.005 -0.591757" rpy="0 0 0"/>
    <geometry>
      <mesh filename="file://$(find capstone_design_description)/meshes/right_gripper_link_1.stl" scale="0.001 0.001 0.001"/>
    </geometry>
  </collision>
</link>

<link name="left_finger_1">
  <inertial>
    <origin xyz="0.01613904694023681 -0.002499999999999998 0.020996703413204365" rpy="0 0 0"/>
    <mass value="0.03447696599229279"/>
    <inertia ixx="1.2e-05" iyy="1.5e-05" izz="3e-06" ixy="-0.0" iyz="0.0" ixz="-4e-06"/>
  </inertial>
  <visual>
    <origin xyz="0.03 -0.0 -0.621757" rpy="0 0 0"/>
    <geometry>
      <mesh filename="file://$(find capstone_design_description)/meshes/left_finger_1.stl" scale="0.001 0.001 0.001"/>
    </geometry>
    <material name="silver"/>
  </visual>
  <collision>
    <origin xyz="0.03 -0.0 -0.621757" rpy="0 0 0"/>
    <geometry>
      <mesh filename="file://$(find capstone_design_description)/meshes/left_finger_1.stl" scale="0.001 0.001 0.001"/>
    </geometry>
  </collision>
</link>

<link name="right_finger_1">
  <inertial>
    <origin xyz="-0.01613904694030094 -0.002499999999999998 0.020996703413204365" rpy="0 0 0"/>
    <mass value="0.034476965992292836"/>
    <inertia ixx="1.2e-05" iyy="1.5e-05" izz="3e-06" ixy="0.0" iyz="0.0" ixz="4e-06"/>
  </inertial>
  <visual>
    <origin xyz="-0.03 -0.0 -0.621757" rpy="0 0 0"/>
    <geometry>
      <mesh filename="file://$(find capstone_design_description)/meshes/right_finger_1.stl" scale="0.001 0.001 0.001"/>
    </geometry>
    <material name="silver"/>
  </visual>
  <collision>
    <origin xyz="-0.03 -0.0 -0.621757" rpy="0 0 0"/>
    <geometry>
      <mesh filename="file://$(find capstone_design_description)/meshes/right_finger_1.stl" scale="0.001 0.001 0.001"/>
    </geometry>
  </collision>
</link>

<link name="right_wheel_1">
  <inertial>
    <origin xyz="0.009299999999999975 -1.3877787807814457e-17 3.469446951953614e-18" rpy="0 0 0"/>
    <mass value="0.49952859430885366"/>
    <inertia ixx="0.000272" iyy="0.00015" izz="0.00015" ixy="-0.0" iyz="0.0" ixz="0.0"/>
  </inertial>
  <visual>
    <origin xyz="-0.1435 -0.07 0.017" rpy="0 0 0"/>
    <geometry>
      <mesh filename="file://$(find capstone_design_description)/meshes/right_wheel_1.stl" scale="0.001 0.001 0.001"/>
    </geometry>
    <material name="silver"/>
  </visual>
  <collision>
    <origin xyz="-0.1435 -0.07 0.017" rpy="0 0 0"/>
    <geometry>
      <mesh filename="file://$(find capstone_design_description)/meshes/right_wheel_1.stl" scale="0.001 0.001 0.001"/>
    </geometry>
  </collision>
</link>

<link name="left_wheel_1">
  <inertial>
    <origin xyz="-0.009300000000000003 0.0 -1.0408340855860843e-17" rpy="0 0 0"/>
    <mass value="0.4995285943088536"/>
    <inertia ixx="0.000272" iyy="0.00015" izz="0.00015" ixy="0.0" iyz="-0.0" ixz="-0.0"/>
  </inertial>
  <visual>
    <origin xyz="0.1435 -0.07 0.017" rpy="0 0 0"/>
    <geometry>
      <mesh filename="file://$(find capstone_design_description)/meshes/left_wheel_1.stl" scale="0.001 0.001 0.001"/>
    </geometry>
    <material name="silver"/>
  </visual>
  <collision>
    <origin xyz="0.1435 -0.07 0.017" rpy="0 0 0"/>
    <geometry>
      <mesh filename="file://$(find capstone_design_description)/meshes/left_wheel_1.stl" scale="0.001 0.001 0.001"/>
    </geometry>
  </collision>
</link>

<link name="lidar_1">
  <inertial>
    <origin xyz="1.06925634351284e-17 -5.551115123125783e-17 0.030000000000000027" rpy="0 0 0"/>
    <mass value="3.3385508780157878"/>
    <inertia ixx="0.002885" iyy="0.002885" izz="0.003766" ixy="0.0" iyz="0.0" ixz="0.0"/>
  </inertial>
  <visual>
    <origin xyz="-0.0 0.296 -0.3977" rpy="0 0 0"/>
    <geometry>
      <mesh filename="file://$(find capstone_design_description)/meshes/lidar_1.stl" scale="0.001 0.001 0.001"/>
    </geometry>
    <material name="silver"/>
  </visual>
  <collision>
    <origin xyz="-0.0 0.296 -0.3977" rpy="0 0 0"/>
    <geometry>
      <mesh filename="file://$(find capstone_design_description)/meshes/lidar_1.stl" scale="0.001 0.001 0.001"/>
    </geometry>
  </collision>
</link>

<link name="stereo_camera_1">
  <inertial>
    <origin xyz="0.0 -0.01499999999999999 2.5403783909805355e-07" rpy="0 0 0"/>
    <mass value="0.5025570000000006"/>
    <inertia ixx="5.8e-05" iyy="0.000414" izz="0.000432" ixy="0.0" iyz="0.0" ixz="0.0"/>
  </inertial>
  <visual>
    <origin xyz="-0.0 0.01 -0.575417" rpy="0 0 0"/>
    <geometry>
      <mesh filename="file://$(find capstone_design_description)/meshes/stereo_camera_1.stl" scale="0.001 0.001 0.001"/>
    </geometry>
    <material name="silver"/>
  </visual>
  <collision>
    <origin xyz="-0.0 0.01 -0.575417" rpy="0 0 0"/>
    <geometry>
      <mesh filename="file://$(find capstone_design_description)/meshes/stereo_camera_1.stl" scale="0.001 0.001 0.001"/>
    </geometry>
  </collision>
</link>

<joint name="base_link_to_arm_base_link" type="revolute">
  <origin xyz="0.0 0.0 0.0918" rpy="0 0 0"/>
  <parent link="base_link"/>
  <child link="arm_base_link_1"/>
  <axis xyz="0.0 0.0 1.0"/>
  <limit upper="1.570796" lower="-1.570796" effort="100" velocity="100"/>
</joint>

<joint name="arm_base_link_to_link1" type="fixed">
  <origin xyz="0.0 0.0 0.01" rpy="0 0 0"/>
  <parent link="arm_base_link_1"/>
  <child link="link1_1"/>
</joint>

<joint name="link1_to_link2" type="revolute">
  <origin xyz="-0.0336 0.0 0.065" rpy="0 0 0"/>
  <parent link="link1_1"/>
  <child link="link2_1"/>
  <axis xyz="-1.0 0.0 0.0"/>
  <limit upper="1.570796" lower="-1.570796" effort="100" velocity="100"/>
</joint>

<joint name="link2_to_link3" type="revolute">
  <origin xyz="0.0036 0.0 0.203557" rpy="0 0 0"/>
  <parent link="link2_1"/>
  <child link="link3_1"/>
  <axis xyz="-1.0 0.0 0.0"/>
  <limit upper="1.570796" lower="-1.570796" effort="100" velocity="100"/>
</joint>

<joint name="link3_to_hand_link" type="revolute">
  <origin xyz="0.022 0.0 0.1739" rpy="0 0 0"/>
  <parent link="link3_1"/>
  <child link="hand_link_1"/>
  <axis xyz="-1.0 0.0 0.0"/>
  <limit upper="1.570796" lower="-1.570796" effort="100" velocity="100"/>
</joint>

<joint name="hand_link_to_left_gripper_link" type="revolute">
  <origin xyz="-0.022 0.005 0.0475" rpy="0 0 0"/>
  <parent link="hand_link_1"/>
  <child link="left_gripper_link_1"/>
  <axis xyz="0.0 1.0 -0.0"/>
  <limit upper="0.0" lower="-1.22173" effort="100" velocity="100"/>
</joint>

<joint name="hand_link_to_right_gripper_link" type="revolute">
  <origin xyz="0.038 0.005 0.0475" rpy="0 0 0"/>
  <parent link="hand_link_1"/>
  <child link="right_gripper_link_1"/>
  <axis xyz="0.0 1.0 -0.0"/>
  <mimic joint="hand_link_to_left_gripper_link" multiplier="-1.0" offset="0.0"/>
  <limit upper="1.22173" lower="0.0" effort="100" velocity="100"/>
</joint>

<joint name="left_gripper_link_to_left_finger" type="revolute">
  <origin xyz="0.0 -0.005 0.03" rpy="0 0 0"/>
  <parent link="left_gripper_link_1"/>
  <child link="left_finger_1"/>
  <axis xyz="0.0 1.0 0.0"/>
  <mimic joint="hand_link_to_left_gripper_link" multiplier="-1.0" offset="0.0"/>
  <limit upper="1.22173" lower="0.0" effort="100" velocity="100"/>
</joint>

<joint name="right_gripper_link_to_right_finger" type="revolute">
  <origin xyz="0.0 -0.005 0.03" rpy="0 0 0"/>
  <parent link="right_gripper_link_1"/>
  <child link="right_finger_1"/>
  <axis xyz="0.0 1.0 0.0"/>
  <mimic joint="hand_link_to_left_gripper_link" multiplier="1.0" offset="0.0"/>
  <limit upper="0.0" lower="-1.22173" effort="100" velocity="100"/>
</joint>

<joint name="right_wheel" type="continuous">
  <origin xyz="0.1435 0.07 -0.017" rpy="0 0 0"/>
  <parent link="base_link"/>
  <child link="right_wheel_1"/>
  <axis xyz="1.0 0.0 0.0"/>
</joint>

<joint name="left_wheel" type="continuous">
  <origin xyz="-0.1435 0.07 -0.017" rpy="0 0 0"/>
  <parent link="base_link"/>
  <child link="left_wheel_1"/>
  <axis xyz="-1.0 0.0 0.0"/>
</joint>

<joint name="lidar" type="fixed">
  <origin xyz="0.0 -0.296 0.3977" rpy="0 0 0"/>
  <parent link="base_link"/>
  <child link="lidar_1"/>
</joint>

<joint name="camera" type="fixed">
  <origin xyz="0.008 -0.01 0.03116" rpy="0 0 0"/>
  <parent link="hand_link_1"/>
  <child link="stereo_camera_1"/>
</joint>

</robot>
